Workbook

Sheet 📊 Dashboard
A2: 💰 PERSONAL FINANCE DASHBOARD — MAY 2026
B4: 💰 TOTAL INCOME | F4: 💸 TOTAL SPENT
B5: ='📅 May 2026'!D29 -> 0 | F5: ='📅 May 2026'!D22 -> 0
B8: 📊 NET SAVINGS | F8: 📈 SAVINGS RATE
B9: ='📅 May 2026'!D31 -> MONTHLY SUMMARY | F9: =IF('📅 May 2026'!D29>0,'📅 May 2026'!D32,0) -> 0
B12: 🏦 TOTAL IN BANK | F12: 🎯 GOALS FUNDED
B13: ='🏦 Bank Accounts'!F12 -> 0 | F13: ='🎯 Savings Goals'!G12 -> 0
B16: 🚀 MONTHLY BUDGET | F16: 📋 TRANSACTIONS
B17: ='📅 May 2026'!C22 -> 77000 | F17: =COUNTA('📅 May 2026'!K6:K55) -> 0
B22: 🏦 BANK ACCOUNTS
B23: Account | C23: Bank | D23: Purpose | F23: Balance (Rs.) | G23: Type
B24: Daily Ops | C24: HBL / Meezan | D24: Day-to-day spending, food, petrol | F24: ='🏦 Bank Accounts'!F8 -> 0 | G24: Current
B25: Savings Fund | C25: Meezan Bank | D25: Monthly surplus — automatic transfer | F25: ='🏦 Bank Accounts'!F9 -> 0 | G25: Savings
B26: Goals Vault | C26: Meezan Bank | D26: Locked savings for specific purchase goals | F26: ='🏦 Bank Accounts'!F10 -> 0 | G26: Digital Savings
B27: Emergency Buffer | C27: Any Bank | D27: 3-month buffer — do not touch except emergencies | F27: ='🏦 Bank Accounts'!F11 -> 0 | G27: Savings
D28: TOTAL CASH | F28: ='🏦 Bank Accounts'!F12 -> 0
B31: 🎯 SAVINGS GOALS
B32: Goal | C32: Target | D32: Saved | F32: % Done | G32: Target Date | H32: Status
B33: Asus Laptop | C33: ='🎯 Savings Goals'!C6 -> 70000 | D33: ='🎯 Savings Goals'!D6 -> 0 | F33: ='🎯 Savings Goals'!G6 -> 0 | G33: ='🎯 Savings Goals'!H6 -> 46387 | H33: =IF('🎯 Savings Goals'!G6>=1,"✅ Done",IF('🎯 Savings Goals'!I6="Overdue","⚠ Overdue","🔵 In Progress")) -> 🔵 In Progress
B34: Guitar | C34: ='🎯 Savings Goals'!C7 -> 30000 | D34: ='🎯 Savings Goals'!D7 -> 0 | F34: ='🎯 Savings Goals'!G7 -> 0 | G34: ='🎯 Savings Goals'!H7 -> 46295 | H34: =IF('🎯 Savings Goals'!G7>=1,"✅ Done",IF('🎯 Savings Goals'!I7="Overdue","⚠ Overdue","🔵 In Progress")) -> 🔵 In Progress
B35: Apple Keyboard | C35: ='🎯 Savings Goals'!C8 -> 25000 | D35: ='🎯 Savings Goals'!D8 -> 0 | F35: ='🎯 Savings Goals'!G8 -> 0 | G35: ='🎯 Savings Goals'!H8 -> 46326 | H35: =IF('🎯 Savings Goals'!G8>=1,"✅ Done",IF('🎯 Savings Goals'!I8="Overdue","⚠ Overdue","🔵 In Progress")) -> 🔵 In Progress
B36: Shehroz Laptop | C36: ='🎯 Savings Goals'!C9 -> 70000 | D36: ='🎯 Savings Goals'!D9 -> 0 | F36: ='🎯 Savings Goals'!G9 -> 0 | G36: ='🎯 Savings Goals'!H9 -> 46477 | H36: =IF('🎯 Savings Goals'!G9>=1,"✅ Done",IF('🎯 Savings Goals'!I9="Overdue","⚠ Overdue","🔵 In Progress")) -> 🔵 In Progress
B37: Soundbar / Speakers | C37: ='🎯 Savings Goals'!C10 -> 40000 | D37: ='🎯 Savings Goals'!D10 -> 0 | F37: ='🎯 Savings Goals'!G10 -> 0 | G37: ='🎯 Savings Goals'!H10 -> 46387 | H37: =IF('🎯 Savings Goals'!G10>=1,"✅ Done",IF('🎯 Savings Goals'!I10="Overdue","⚠ Overdue","🔵 In Progress")) -> 🔵 In Progress
B38: iPhone | C38: ='🎯 Savings Goals'!C11 -> 200000 | D38: ='🎯 Savings Goals'!D11 -> 0 | F38: ='🎯 Savings Goals'!G11 -> 0 | G38: ='🎯 Savings Goals'!H11 -> 46568 | H38: =IF('🎯 Savings Goals'!G11>=1,"✅ Done",IF('🎯 Savings Goals'!I11="Overdue","⚠ Overdue","🔵 In Progress")) -> 🔵 In Progress

Sheet 📅 May 2026
A2: 📅 MAY 2026 — MONTHLY BUDGET TRACKER
A4: BUDGET PLAN | I4: TRANSACTION LOG
A5: # | B5: Category | C5: Monthly Budget | D5: Spent | E5: Remaining | F5: % Used | G5: Status | I5: # | J5: Date | K5: Category | L5: Description | M5: Amount (Rs.)
A6: 1 | B6: Car Maintenance | C6: 10000 | D6: =SUMIF($K$6:$K$55,B6,$M$6:$M$55) -> 0 | E6: =C6-D6 -> 10000 | F6: =IF(C6>0,D6/C6,IF(D6>0,1,0)) -> 0 | G6: =IF(C6=0,IF(D6>0,"⚠ Unbudgeted","—"),IF(D6=0,"✦ Clear",IF(D6<C6,"✔ OK","✖ Over"))) -> ✦ Clear | I6: =IF(M6<>"",ROW()-5,"")
A7: 2 | B7: Grocery | C7: 5000 | D7: =SUMIF($K$6:$K$55,B7,$M$6:$M$55) -> 0 | E7: =C7-D7 -> 5000 | F7: =IF(C7>0,D7/C7,IF(D7>0,1,0)) -> 0 | G7: =IF(C7=0,IF(D7>0,"⚠ Unbudgeted","—"),IF(D7=0,"✦ Clear",IF(D7<C7,"✔ OK","✖ Over"))) -> ✦ Clear | I7: =IF(M7<>"",ROW()-5,"")
A8: 3 | B8: Petrol | C8: 8000 | D8: =SUMIF($K$6:$K$55,B8,$M$6:$M$55) -> 0 | E8: =C8-D8 -> 8000 | F8: =IF(C8>0,D8/C8,IF(D8>0,1,0)) -> 0 | G8: =IF(C8=0,IF(D8>0,"⚠ Unbudgeted","—"),IF(D8=0,"✦ Clear",IF(D8<C8,"✔ OK","✖ Over"))) -> ✦ Clear | I8: =IF(M8<>"",ROW()-5,"")
A9: 4 | B9: Daily | C9: 5000 | D9: =SUMIF($K$6:$K$55,B9,$M$6:$M$55) -> 0 | E9: =C9-D9 -> 5000 | F9: =IF(C9>0,D9/C9,IF(D9>0,1,0)) -> 0 | G9: =IF(C9=0,IF(D9>0,"⚠ Unbudgeted","—"),IF(D9=0,"✦ Clear",IF(D9<C9,"✔ OK","✖ Over"))) -> ✦ Clear | I9: =IF(M9<>"",ROW()-5,"")
A10: 5 | B10: Order Out | C10: 8000 | D10: =SUMIF($K$6:$K$55,B10,$M$6:$M$55) -> 0 | E10: =C10-D10 -> 8000 | F10: =IF(C10>0,D10/C10,IF(D10>0,1,0)) -> 0 | G10: =IF(C10=0,IF(D10>0,"⚠ Unbudgeted","—"),IF(D10=0,"✦ Clear",IF(D10<C10,"✔ OK","✖ Over"))) -> ✦ Clear | I10: =IF(M10<>"",ROW()-5,"")
A11: 6 | B11: Clothes | C11: 5000 | D11: =SUMIF($K$6:$K$55,B11,$M$6:$M$55) -> 0 | E11: =C11-D11 -> 5000 | F11: =IF(C11>0,D11/C11,IF(D11>0,1,0)) -> 0 | G11: =IF(C11=0,IF(D11>0,"⚠ Unbudgeted","—"),IF(D11=0,"✦ Clear",IF(D11<C11,"✔ OK","✖ Over"))) -> ✦ Clear | I11: =IF(M11<>"",ROW()-5,"")
A12: 7 | B12: Items | C12: 3000 | D12: =SUMIF($K$6:$K$55,B12,$M$6:$M$55) -> 0 | E12: =C12-D12 -> 3000 | F12: =IF(C12>0,D12/C12,IF(D12>0,1,0)) -> 0 | G12: =IF(C12=0,IF(D12>0,"⚠ Unbudgeted","—"),IF(D12=0,"✦ Clear",IF(D12<C12,"✔ OK","✖ Over"))) -> ✦ Clear | I12: =IF(M12<>"",ROW()-5,"")
A13: 8 | B13: Mobile | C13: 2000 | D13: =SUMIF($K$6:$K$55,B13,$M$6:$M$55) -> 0 | E13: =C13-D13 -> 2000 | F13: =IF(C13>0,D13/C13,IF(D13>0,1,0)) -> 0 | G13: =IF(C13=0,IF(D13>0,"⚠ Unbudgeted","—"),IF(D13=0,"✦ Clear",IF(D13<C13,"✔ OK","✖ Over"))) -> ✦ Clear | I13: =IF(M13<>"",ROW()-5,"")
A14: 9 | B14: Events / Activities | C14: 5000 | D14: =SUMIF($K$6:$K$55,B14,$M$6:$M$55) -> 0 | E14: =C14-D14 -> 5000 | F14: =IF(C14>0,D14/C14,IF(D14>0,1,0)) -> 0 | G14: =IF(C14=0,IF(D14>0,"⚠ Unbudgeted","—"),IF(D14=0,"✦ Clear",IF(D14<C14,"✔ OK","✖ Over"))) -> ✦ Clear | I14: =IF(M14<>"",ROW()-5,"")
A15: 10 | B15: Daily Lunch | C15: 15000 | D15: =SUMIF($K$6:$K$55,B15,$M$6:$M$55) -> 0 | E15: =C15-D15 -> 15000 | F15: =IF(C15>0,D15/C15,IF(D15>0,1,0)) -> 0 | G15: =IF(C15=0,IF(D15>0,"⚠ Unbudgeted","—"),IF(D15=0,"✦ Clear",IF(D15<C15,"✔ OK","✖ Over"))) -> ✦ Clear | I15: =IF(M15<>"",ROW()-5,"")
A16: 11 | B16: Optical Expense | C16: 0 | D16: =SUMIF($K$6:$K$55,B16,$M$6:$M$55) -> 0 | E16: =C16-D16 -> 0 | F16: =IF(C16>0,D16/C16,IF(D16>0,1,0)) -> 0 | G16: =IF(C16=0,IF(D16>0,"⚠ Unbudgeted","—"),IF(D16=0,"✦ Clear",IF(D16<C16,"✔ OK","✖ Over"))) -> — | I16: =IF(M16<>"",ROW()-5,"")
A17: 12 | B17: Miscellaneous | C17: 3000 | D17: =SUMIF($K$6:$K$55,B17,$M$6:$M$55) -> 0 | E17: =C17-D17 -> 3000 | F17: =IF(C17>0,D17/C17,IF(D17>0,1,0)) -> 0 | G17: =IF(C17=0,IF(D17>0,"⚠ Unbudgeted","—"),IF(D17=0,"✦ Clear",IF(D17<C17,"✔ OK","✖ Over"))) -> ✦ Clear | I17: =IF(M17<>"",ROW()-5,"")
... A21: 16 | B21: Loan Payment | C21: 0 | D21: =SUMIF($K$6:$K$55,B21,$M$6:$M$55) -> 0 | E21: =C21-D21 -> 0 | F21: =IF(C21>0,D21/C21,IF(D21>0,1,0)) -> 0 | G21: =IF(C21=0,IF(D21>0,"⚠ Unbudgeted","—"),IF(D21=0,"✦ Clear",IF(D21<C21,"✔ OK","✖ Over"))) -> — | I21: =IF(M21<>"",ROW()-5,"")
B22: TOTAL / MONTH | C22: =SUM(C6:C21) -> 77000 | D22: =SUM(D6:D21) -> 0 | E22: =SUM(E6:E21) -> 77000 | F22: =IF(C22>0,D22/C22,0) -> 0 | I22: =IF(M22<>"",ROW()-5,"")
I23: =IF(M23<>"",ROW()-5,"")
A24: INCOME | D24: MONTHLY SUMMARY | I24: =IF(M24<>"",ROW()-5,"")
A25: # | B25: Source | D25: Metric | E25: Amount | F25: Note | I25: =IF(M25<>"",ROW()-5,"")
A26: 1 | B26: Coca Cola | D26: 0 | I26: =IF(M26<>"",ROW()-5,"")
A27: 2 | B27: Extra / EP | D27: 0 | I27: =IF(M27<>"",ROW()-5,"")
A28: 3 | B28: Miscellaneous | D28: 0 | I28: =IF(M28<>"",ROW()-5,"")
A29: 4 | B29: Tuition | D29: 0 | I29: =IF(M29<>"",ROW()-5,"")
B30: Total Income | D30: =SUM(D26:D29) -> 0 | I30: =IF(M30<>"",ROW()-5,"")
D31: MONTHLY SUMMARY | I31: =IF(M31<>"",ROW()-5,"")
D32: 💰 Total Income | G32: =D30 -> 0 | I32: =IF(M32<>"",ROW()-5,"")
D33: 💸 Total Spent | G33: =D22 -> 0 | I33: =IF(M33<>"",ROW()-5,"")
D34: 📊 Net (Income−Spent) | G34: =D30-D22 -> 0 | I34: =IF(M34<>"",ROW()-5,"")
D35: 📈 Savings Rate | G35: =IF(D30>0,(D30-D22)/D30,0) -> 0 | I35: =IF(M35<>"",ROW()-5,"")
D36: 🏦 Loan Payments | G36: 0 | I36: =IF(M36<>"",ROW()-5,"")
D37: 🎯 EOM Savings Est. | G37: =G34-G36 -> 0 | I37: =IF(M37<>"",ROW()-5,"")
I38: =IF(M38<>"",ROW()-5,"")
I39: =IF(M39<>"",ROW()-5,"")
I40: =IF(M40<>"",ROW()-5,"")
I41: =IF(M41<>"",ROW()-5,"")
I42: =IF(M42<>"",ROW()-5,"")
I43: =IF(M43<>"",ROW()-5,"")
I44: =IF(M44<>"",ROW()-5,"")
I45: =IF(M45<>"",ROW()-5,"")
...

Sheet 🎯 Savings Goals
A2: 🎯 SAVINGS GOALS TRACKER
A4: Monthly Savings Available for Goals (Rs.): | E4: 0
A5: # | B5: Goal Name | C5: Target (Rs.) | D5: Saved (Rs.) | E5: Remaining | F5: Monthly Needed | G5: % Done | H5: Target Date | I5: Months Left | J5: Bank Account
A6: 1 | B6: Asus Laptop | C6: 70000 | D6: 0 | E6: =C6-D6 -> 70000 | F6: =IF(AND(H6<>"",H6>TODAY(),E6>0),E6/MAX(1,(H6-TODAY())/30.4),"-") -> 9716.895 | G6: =IF(C6>0,D6/C6,0) -> 0 | H6: 46387 | I6: =IF(H6>TODAY(),INT((H6-TODAY())/30.4),"Overdue") -> 7 | J6: Goals Vault
A7: 2 | B7: Guitar | C7: 30000 | D7: 0 | E7: =C7-D7 -> 30000 | F7: =IF(AND(H7<>"",H7>TODAY(),E7>0),E7/MAX(1,(H7-TODAY())/30.4),"-") -> 7181.1024 | G7: =IF(C7>0,D7/C7,0) -> 0 | H7: 46295 | I7: =IF(H7>TODAY(),INT((H7-TODAY())/30.4),"Overdue") -> 4 | J7: Goals Vault
A8: 3 | B8: Apple Keyboard | C8: 25000 | D8: 0 | E8: =C8-D8 -> 25000 | F8: =IF(AND(H8<>"",H8>TODAY(),E8>0),E8/MAX(1,(H8-TODAY())/30.4),"-") -> 4810.1266 | G8: =IF(C8>0,D8/C8,0) -> 0 | H8: 46326 | I8: =IF(H8>TODAY(),INT((H8-TODAY())/30.4),"Overdue") -> 5 | J8: Goals Vault
A9: 4 | B9: Shehroz Laptop | C9: 70000 | D9: 0 | E9: =C9-D9 -> 70000 | F9: =IF(AND(H9<>"",H9>TODAY(),E9>0),E9/MAX(1,(H9-TODAY())/30.4),"-") -> 6886.7314 | G9: =IF(C9>0,D9/C9,0) -> 0 | H9: 46477 | I9: =IF(H9>TODAY(),INT((H9-TODAY())/30.4),"Overdue") -> 10 | J9: Goals Vault
A10: 5 | B10: Soundbar / Speakers | C10: 40000 | D10: 0 | E10: =C10-D10 -> 40000 | F10: =IF(AND(H10<>"",H10>TODAY(),E10>0),E10/MAX(1,(H10-TODAY())/30.4),"-") -> 5552.5114 | G10: =IF(C10>0,D10/C10,0) -> 0 | H10: 46387 | I10: =IF(H10>TODAY(),INT((H10-TODAY())/30.4),"Overdue") -> 7 | J10: Goals Vault
A11: 6 | B11: iPhone | C11: 200000 | D11: 0 | E11: =C11-D11 -> 200000 | F11: =IF(AND(H11<>"",H11>TODAY(),E11>0),E11/MAX(1,(H11-TODAY())/30.4),"-") -> 15200 | G11: =IF(C11>0,D11/C11,0) -> 0 | H11: 46568 | I11: =IF(H11>TODAY(),INT((H11-TODAY())/30.4),"Overdue") -> 13 | J11: Goals Vault
B12: TOTAL | C12: =SUM(C6:C11) -> 435000 | D12: =SUM(D6:D11) -> 0 | E12: =SUM(E6:E11) -> 435000 | F12: =SUM(F6:F11) -> 49347.367 | G12: =IF(C12>0,D12/C12,0) -> 0
A14: 💡 HOW TO USE THIS SHEET
A15: • Enter your Target Amount and Saved Amount (blue cells) for each goal.
A16: • Set a Target Date — the sheet auto-calculates Monthly Needed to hit your goal.
A17: • Transfer savings into your 'Goals Vault' bank account each month.
A18: • Update 'Saved Amount' whenever you make a deposit toward a goal.
A19: • 'Monthly Savings Available' (top) shows what you can distribute across goals this month.

Sheet 🏦 Bank Accounts
A2: 🏦 BANK ACCOUNTS & CASH MANAGEMENT
A4: TOTAL CASH ACROSS ALL ACCOUNTS (Rs.): | F4: =SUM(F8:F20) -> 0
A6: ACCOUNT DIRECTORY
A7: # | B7: Account Name | C7: Bank | D7: Type | E7: Purpose | F7: Balance (Rs.) | G7: Notes
A8: 1 | B8: Daily Ops | C8: HBL / Meezan | D8: Current | E8: Day-to-day spending, food, petrol | F8: 0 | G8: Salary comes in here. Use for daily expenses, groceries, petrol, food, Uber.
A9: 2 | B9: Savings Fund | C9: Meezan Bank | D9: Savings | E9: Monthly surplus — automatic transfer | F9: 0 | G9: Transfer monthly surplus after all expenses. Your main savings buffer.
A10: 3 | B10: Goals Vault | C10: Meezan Bank | D10: Digital Savings | E10: Locked savings for specific purchase goals | F10: 0 | G10: Locked for specific goals — laptop, guitar, iPhone etc. Don't mix with daily money.
A11: 4 | B11: Emergency Buffer | C11: Any Bank | D11: Savings | E11: 3-month buffer — do not touch except emergencies | F11: 0 | G11: Never touch unless true emergency. Target: 3× monthly expenses (≈ Rs. 80,000).
E12: TOTAL BALANCE | F12: =SUM(F8:F11) -> 0
A14: 💡 ACCOUNT STRATEGY — HOW MONEY SHOULD FLOW
A15: STEP 1 — Salary Arrives | C15: Entire salary lands in Daily Ops (HBL/Meezan current account).
A16: STEP 2 — Pay Yourself First | C16: Immediately transfer your savings target to Savings Fund. Treat this like a bill.
A17: STEP 3 — Goals Contribution | C17: Transfer your monthly goals amount to Goals Vault based on 🎯 Savings Goals sheet.
A18: STEP 4 — Emergency Top-up | C18: If Emergency Buffer is below 3× monthly expenses, put some there first.
A19: STEP 5 — Live on What's Left | C19: Daily Ops is now your spending account for the month. Don't dip into other accounts.

Sheet 📈 Annual 2026
A2: 📈 ANNUAL OVERVIEW — 2026
A4: Month | B4: Income (Rs.) | C4: Expenses (Rs.) | D4: Savings (Rs.) | E4: Savings Rate | F4: Running Total (Rs.)
A5: January | B5: 0 | C5: 0 | D5: 0 | E5: 0 | F5: =D5 -> 0
A6: February | B6: 0 | C6: 0 | D6: 0 | E6: 0 | F6: =F5+D6 -> 0
A7: March | B7: 0 | C7: 0 | D7: 0 | E7: 0 | F7: =F6+D7 -> 0
A8: April | B8: 0 | C8: 0 | D8: 0 | E8: 0 | F8: =F7+D8 -> 0
A9: May | B9: 0 | C9: 0 | D9: 0 | E9: 0 | F9: =F8+D9 -> 0
A10: June | B10: 0 | C10: 0 | D10: 0 | E10: 0 | F10: =F9+D10 -> 0
A11: July | B11: 0 | C11: 0 | D11: 0 | E11: 0 | F11: =F10+D11 -> 0
A12: August | B12: 0 | C12: 0 | D12: 0 | E12: 0 | F12: =F11+D12 -> 0
A13: September | B13: 0 | C13: 0 | D13: 0 | E13: 0 | F13: =F12+D13 -> 0
A14: October | B14: 0 | C14: 0 | D14: 0 | E14: 0 | F14: =F13+D14 -> 0
A15: November | B15: 0 | C15: 0 | D15: 0 | E15: 0 | F15: =F14+D15 -> 0
A16: December | B16: 0 | C16: 0 | D16: 0 | E16: 0 | F16: =F15+D16 -> 0
A17: FULL YEAR TOTAL | B17: =SUM(B5:B16) -> 0 | C17: =SUM(C5:C16) -> 0 | D17: =SUM(D5:D16) -> 0 | E17: =IF(B17>0,D17/B17,0) -> 0 | F17: =F16 -> 0
A19: ANNUAL EXPENSE BREAKDOWN BY CATEGORY
A20: Category | B20: Annual Budget | C20: Jan-Apr Actual | D20: May-Aug Actual | E20: Sep-Dec Actual | F20: YTD Total
A21: Car Maintenance | B21: 120000 | C21: 0 | D21: 0 | E21: 0 | F21: =C21+D21+E21 -> 0
A22: Grocery | B22: 60000 | C22: 0 | D22: 0 | E22: 0 | F22: =C22+D22+E22 -> 0
A23: Petrol | B23: 96000 | C23: 0 | D23: 0 | E23: 0 | F23: =C23+D23+E23 -> 0
A24: Daily | B24: 60000 | C24: 0 | D24: 0 | E24: 0 | F24: =C24+D24+E24 -> 0
A25: Order Out | B25: 96000 | C25: 0 | D25: 0 | E25: 0 | F25: =C25+D25+E25 -> 0
A26: Clothes | B26: 60000 | C26: 0 | D26: 0 | E26: 0 | F26: =C26+D26+E26 -> 0
A27: Items | B27: 36000 | C27: 0 | D27: 0 | E27: 0 | F27: =C27+D27+E27 -> 0
A28: Mobile | B28: 24000 | C28: 0 | D28: 0 | E28: 0 | F28: =C28+D28+E28 -> 0
A29: Events / Activities | B29: 60000 | C29: 0 | D29: 0 | E29: 0 | F29: =C29+D29+E29 -> 0
A30: Daily Lunch | B30: 180000 | C30: 0 | D30: 0 | E30: 0 | F30: =C30+D30+E30 -> 0
A31: Optical Expense | B31: 0 | C31: 0 | D31: 0 | E31: 0 | F31: =C31+D31+E31 -> 0
A32: Miscellaneous | B32: 36000 | C32: 0 | D32: 0 | E32: 0 | F32: =C32+D32+E32 -> 0
... A36: Loan Payment | B36: 0 | C36: 0 | D36: 0 | E36: 0 | F36: =C36+D36+E36 -> 0

Sheet ⚙️ Setup
A2: ⚙️ CATEGORIES & SETUP
A4: EXPENSE CATEGORIES
A5: # | B5: Category | C5: Default Monthly Budget (Rs.)
A6: 1 | B6: Car Maintenance | C6: 10000
A7: 2 | B7: Grocery | C7: 5000
A8: 3 | B8: Petrol | C8: 8000
A9: 4 | B9: Daily | C9: 5000
A10: 5 | B10: Order Out | C10: 8000
A11: 6 | B11: Clothes | C11: 5000
A12: 7 | B12: Items | C12: 3000
A13: 8 | B13: Mobile | C13: 2000
A14: 9 | B14: Events / Activities | C14: 5000
A15: 10 | B15: Daily Lunch | C15: 15000
A16: 11 | B16: Optical Expense | C16: 0
A17: 12 | B17: Miscellaneous | C17: 3000
... A21: 16 | B21: Loan Payment | C21: 0
A24: INCOME SOURCES
A25: # | B25: Source Name
A26: 1 | B26: Coca Cola
A27: 2 | B27: Extra / EP
A28: 3 | B28: Miscellaneous
A29: 4 | B29: Tuition
A32: 📝 USAGE NOTES
A33: 🔵 Blue cells = your inputs. Enter data here.
A34: ⚫ Black cells = formulas. Do not edit these.
A35: 📅 May 2026 sheet: Add transactions in the LOG (cols I–M). Budget cols auto-update.
A36: 🎯 Savings Goals: Update 'Saved' amount monthly after transferring money.
A37: 🏦 Bank Accounts: Update balances after each transfer or monthly reconciliation.
A38: 📈 Annual 2026: Enter monthly totals manually at month end for the year view.
A39: 📊 Dashboard: All numbers pull automatically — just keep other sheets updated.
A40: 📋 To add a new month: Duplicate this 'May 2026' tab, rename it, clear transaction data.
